<?xml version="1.0"?>
<robot name="robot" xmlns:xacro="http://ros.org/wiki/xacro">

  <!-- Define robot constants -->
  <xacro:property name="base_width" value="0.31"/>
  <xacro:property name="base_length" value="0.42"/>
  <xacro:property name="base_height" value="0.18"/>

  <xacro:property name="front_width" value="0.05"/>
  <xacro:property name="front_length" value="0.05"/>
  <xacro:property name="front_height" value="0.08"/>

  <xacro:property name="wheel_radius" value="0.5"/>
  <xacro:property name="wheel_width" value="0.04"/>
  <xacro:property name="wheel_ygap" value="0.025"/>
  <xacro:property name="wheel_zoff" value="0.1"/>
  <xacro:property name="wheel_xoff" value="0.12"/>

  <xacro:property name="front_wheel_xoff" value="-0.14"/>
  <xacro:property name="front_wheel_ygap" value="0.005"/>

  <link name="base_link">
    <visual>
      <geometry>
        <box size="${base_length} ${base_width} ${base_height}"/>
      </geometry>
      <material name="Cyan">
        <color rgba="0 1.0 1.0 1.0"/>
      </material>
    </visual>
  </link>

  <link name="front_link">
<inertial>
         <mass value="1"/>
         <inertia ixx="100"  ixy="0"  ixz="0" iyy="100" iyz="0" izz="100" />
       </inertial>

  
<visual>
      <geometry>
        <box size="${front_length} ${front_width} ${front_height}"/>
      </geometry>
      <material name="Cyan">
        <color rgba="0 1.0 1.0 1.0"/>
      </material>
    </visual>


  </link>

  <joint name="front_joint" type="fixed">
    <parent link="base_link"/>
    <child link="front_link"/>
    <origin xyz="${(base_length+front_length)/2} 0.0 ${front_height/2}" rpy="0 0 0"/>
  </joint>

  <link name="servo_link">
<inertial>
         <mass value="1"/>
         <inertia ixx="100"  ixy="0"  ixz="0" iyy="100" iyz="0" izz="100" />
       </inertial>

   
 <visual>
        <origin xyz="0 0 0" rpy="$0 0 ${pi/2}"/>
        <geometry>
            <cylinder radius="${front_width/2}" length="0.1"/>
        </geometry>
        <material name="Gray">
          <color rgba="0.5 0.5 0.5 1.0"/>
        </material>
      </visual>
  </link>

  <joint name="servo_joint" type="revolute">
    <parent link="front_link"/>
      <child link="servo_link"/>
      <origin xyz="0.0 0.0 ${-(front_height/2)}" rpy="0 0 0"/>
      <axis xyz="0 0 1"/>
    <limit effort="10.0" lower="-1.57" upper="1.57" velocity="0.5"/>
    </joint>



  <!-- Robot Footprint -->
  <link name="base_footprint">
<inertial>
         <mass value="1"/>
         <inertia ixx="100"  ixy="0"  ixz="0" iyy="100" iyz="0" izz="100" />
       </inertial>


</link>

  <joint name="base_joint" type="fixed">
    <parent link="base_link"/>
    <child link="base_footprint"/>
    <origin xyz="0.0 0.0 ${-(wheel_radius+wheel_zoff)}" rpy="0 0 0"/>
  </joint>
<!-- Wheels -->
  <xacro:macro name="wheel" params="prefix x_reflect y_reflect">
    <link name="${prefix}_link">
<inertial>
         <mass value="1"/>
         <inertia ixx="100"  ixy="0"  ixz="0" iyy="100" iyz="0" izz="100" />
       </inertial>

      
<visual>
        <origin xyz="0 0 0" rpy="${pi/2} 0 0"/>
        <geometry>
            <cylinder radius="${wheel_radius}" length="${wheel_width}"/>
        </geometry>
        <material name="Gray">
          <color rgba="0.5 0.5 0.5 1.0"/>
        </material>
      </visual>
    </link>

    <joint name="${prefix}_joint" type="continuous">
      <parent link="base_link"/>
      <child link="${prefix}_link"/>
      <origin xyz="${x_reflect*wheel_xoff} ${y_reflect*(base_width/2+wheel_ygap)} ${-wheel_zoff}" rpy="0 0 0"/>
      <axis xyz="0 1 0"/>
    </joint>
  </xacro:macro>

  <xacro:wheel prefix="drivewhl_l" x_reflect="-1" y_reflect="1" />
  <xacro:wheel prefix="drivewhl_r" x_reflect="-1" y_reflect="-1" />

<!-- Front Wheels -->
  <xacro:macro name="front_wheel" params="prefix x_reflect y_reflect">
    <link name="${prefix}_link">
<inertial>
         <mass value="1"/>
         <inertia ixx="100"  ixy="0"  ixz="0" iyy="100" iyz="0" izz="100" />
       </inertial>

      
<visual>
        <origin xyz="0 0 0" rpy="${pi/2} 0 0"/>
        <geometry>
            <cylinder radius="${wheel_radius}" length="${wheel_width}"/>
        </geometry>
        <material name="Gray">
          <color rgba="0.5 0.5 0.5 1.0"/>
        </material>
      </visual>
    </link>

    <joint name="${prefix}_joint" type="continuous">
      <parent link="servo_link"/>
      <child link="${prefix}_link"/>
      <origin xyz="0.0 ${y_reflect*(front_width/2+front_wheel_ygap)} ${-wheel_zoff}" rpy="0 0 0"/>
      <axis xyz="0 1 0"/>
    </joint>
  </xacro:macro>

  <xacro:front_wheel prefix="front_whl_l" x_reflect="-1" y_reflect="1" />
  <xacro:front_wheel prefix="front_whl_r" x_reflect="-1" y_reflect="-1"/>

<gazebo>
  <plugin name='diff_drive' filename='libgazebo_ros_diff_drive.so'>
    <ros>
      <namespace>/demo</namespace>
    </ros>

    <!-- wheels -->
    <left_joint>drivewhl_l_joint</left_joint>
    <right_joint>drivewhl_r_joint</right_joint>

    <!-- kinematics -->
    <wheel_separation>0.4</wheel_separation>
    <wheel_diameter>0.2</wheel_diameter>

    <!-- limits -->
    <max_wheel_torque>20</max_wheel_torque>
    <max_wheel_acceleration>1.0</max_wheel_acceleration>

    <!-- output -->
    <publish_odom>true</publish_odom>
    <publish_odom_tf>false</publish_odom_tf>
    <publish_wheel_tf>true</publish_wheel_tf>

    <odometry_frame>odom</odometry_frame>
    <robot_base_frame>base_link</robot_base_frame>
  </plugin>
</gazebo>
</robot>
